Workbook

Sheet Netflix_Data
A1: Content_ID | B1: Title | C1: Type | D1: Genre | E1: Release_Year | F1: Country | G1: Date_Added | H1: Duration_Min | I1: Age_Rating | J1: IMDb_Rating | K1: Views_Millions | L1: Language | M1: Director | N1: Lead_Actor | O1: Seasons | P1: Budget_Million_USD | Q1: Revenue_Million_USD | R1: CONTENT_STATUS | S1: POPULARITY | T1: FAMILY_CONTENT | U1: BUDGET | V1: PROFIT | W1: ROI%
A2: NFX-100001 | B2: Fading City 2 | C2: Movie | D2: Drama | E2: 2016 | F2: UK | G2: 2020-06-15 | H2: 172 | I2: 16+ | J2: 9 | K2: 441.1 | L2: Spanish | M2: Anurag Kashyap | N2: Ranbir Kapoor | P2: 31 | Q2: 195.2 | R2: =_xlfn.IFS(J2>=8,"Hit",J2>=6,"Average",J2<6,"Flop") -> Hit | S2: =_xlfn.IFS(K2>=400,"Blockbuster",K2>=200,"Popular",K2<200,"Normal") -> Blockbuster | T2: =IF(OR(I2="PG",I2="G"),"Yes","No") -> No | U2: =IF(P2>=100,"High","Low") -> Low | V2: =Q2-P2 -> 164.2 | W2: =(Q2/P2)*100 -> 629.67742
A3: NFX-100002 | B3: Crystal Frontier | C3: Movie | D3: Romance | E3: 2005 | F3: South Korea | G3: 2022-06-04 | H3: 143 | I3: PG-13 | J3: 7.4 | K3: 304.3 | L3: English | M3: Quentin Tarantino | N3: Jennifer Lawrence | P3: 63 | Q3: 143.5 | R3: =_xlfn.IFS(J3>=8,"Hit",J3>=6,"Average",J3<6,"Flop") -> Average | S3: =_xlfn.IFS(K3>=400,"Blockbuster",K3>=200,"Popular",K3<200,"Normal") -> Popular | T3: =IF(OR(I3="PG",I3="G"),"Yes","No") -> No | U3: =IF(P3>=100,"High","Low") -> Low | V3: =Q3-P3 -> 80.5 | W3: =(Q3/P3)*100 -> 227.77778
A4: NFX-100003 | B4: Last Journey 6 | C4: Movie | D4: Adventure | E4: 2018 | F4: India | G4: 2019-06-06 | H4: 86 | I4: PG | J4: 7.9 | K4: 88.6 | L4: French | M4: Christopher Nolan | N4: Timothée Chalamet | P4: 107 | Q4: 379.1 | R4: =_xlfn.IFS(J4>=8,"Hit",J4>=6,"Average",J4<6,"Flop") -> Average | S4: =_xlfn.IFS(K4>=400,"Blockbuster",K4>=200,"Popular",K4<200,"Normal") -> Normal | T4: =IF(OR(I4="PG",I4="G"),"Yes","No") -> Yes | U4: =IF(P4>=100,"High","Low") -> High | V4: =Q4-P4 -> 272.1 | W4: =(Q4/P4)*100 -> 354.29907
A5: NFX-100004 | B5: Crystal Odyssey | C5: TV Show | D5: Thriller | E5: 2007 | F5: Canada | G5: 2022-01-02 | H5: 49 | I5: G | J5: 5.9 | K5: 313.2 | L5: Spanish | M5: Christopher Nolan | N5: Ranbir Kapoor | O5: 3 | P5: 128 | Q5: 564.8 | R5: =_xlfn.IFS(J5>=8,"Hit",J5>=6,"Average",J5<6,"Flop") -> Flop | S5: =_xlfn.IFS(K5>=400,"Blockbuster",K5>=200,"Popular",K5<200,"Normal") -> Popular | T5: =IF(OR(I5="PG",I5="G"),"Yes","No") -> Yes | U5: =IF(P5>=100,"High","Low") -> High | V5: =Q5-P5 -> 436.8 | W5: =(Q5/P5)*100 -> 441.25
A6: NFX-100005 | B6: Dark Archive 8 | C6: Movie | D6: Drama | E6: 2007 | F6: India | G6: 2021-12-14 | H6: 95 | I6: PG-13 | J6: 4.6 | K6: 373.8 | L6: French | M6: Rajkumar Hirani | N6: Tom Hardy | P6: 86 | Q6: 168.7 | R6: =_xlfn.IFS(J6>=8,"Hit",J6>=6,"Average",J6<6,"Flop") -> Flop | S6: =_xlfn.IFS(K6>=400,"Blockbuster",K6>=200,"Popular",K6<200,"Normal") -> Popular | T6: =IF(OR(I6="PG",I6="G"),"Yes","No") -> No | U6: =IF(P6>=100,"High","Low") -> Low | V6: =Q6-P6 -> 82.7 | W6: =(Q6/P6)*100 -> 196.16279
A7: NFX-100006 | B7: Broken Empire | C7: TV Show | D7: Crime | E7: 2022 | F7: India | G7: 2023-11-15 | H7: 55 | I7: PG-13 | J7: 8.2 | K7: 134.9 | L7: English | M7: Rajkumar Hirani | N7: Brad Pitt | O7: 5 | P7: 37 | Q7: 74.1 | R7: =_xlfn.IFS(J7>=8,"Hit",J7>=6,"Average",J7<6,"Flop") -> Hit | S7: =_xlfn.IFS(K7>=400,"Blockbuster",K7>=200,"Popular",K7<200,"Normal") -> Normal | T7: =IF(OR(I7="PG",I7="G"),"Yes","No") -> No | U7: =IF(P7>=100,"High","Low") -> Low | V7: =Q7-P7 -> 37.1 | W7: =(Q7/P7)*100 -> 200.27027
A8: NFX-100007 | B8: Broken Legacy | C8: TV Show | D8: Action | E8: 2006 | F8: India | G8: 2022-06-28 | H8: 35 | I8: G | J8: 5 | K8: 446.5 | L8: Japanese | M8: Park Chan-wook | N8: Leonardo DiCaprio | O8: 1 | P8: 102 | Q8: 133.6 | R8: =_xlfn.IFS(J8>=8,"Hit",J8>=6,"Average",J8<6,"Flop") -> Flop | S8: =_xlfn.IFS(K8>=400,"Blockbuster",K8>=200,"Popular",K8<200,"Normal") -> Blockbuster | T8: =IF(OR(I8="PG",I8="G"),"Yes","No") -> Yes | U8: =IF(P8>=100,"High","Low") -> High | V8: =Q8-P8 -> 31.6 | W8: =(Q8/P8)*100 -> 130.98039
A9: NFX-100008 | B9: Silent Horizon | C9: Movie | D9: Drama | E9: 2021 | F9: South Korea | G9: 2018-03-28 | H9: 125 | I9: G | J9: 8.9 | K9: 497.1 | L9: Hindi | M9: Steven Spielberg | N9: Leonardo DiCaprio | P9: 170 | Q9: 468.9 | R9: =_xlfn.IFS(J9>=8,"Hit",J9>=6,"Average",J9<6,"Flop") -> Hit | S9: =_xlfn.IFS(K9>=400,"Blockbuster",K9>=200,"Popular",K9<200,"Normal") -> Blockbuster | T9: =IF(OR(I9="PG",I9="G"),"Yes","No") -> Yes | U9: =IF(P9>=100,"High","Low") -> High | V9: =Q9-P9 -> 298.9 | W9: =(Q9/P9)*100 -> 275.82353
A10: NFX-100009 | B10: Midnight Empire 5 | C10: TV Show | D10: Fantasy | E10: 2005 | F10: Spain | G10: 2019-11-09 | H10: 52 | I10: G | J10: 4.9 | K10: 590.4 | L10: Spanish | M10: Guillermo del Toro | N10: Chris Evans | O10: 2 | P10: 38 | Q10: 141 | R10: =_xlfn.IFS(J10>=8,"Hit",J10>=6,"Average",J10<6,"Flop") -> Flop | S10: =_xlfn.IFS(K10>=400,"Blockbuster",K10>=200,"Popular",K10<200,"Normal") -> Blockbuster | T10: =IF(OR(I10="PG",I10="G"),"Yes","No") -> Yes | U10: =IF(P10>=100,"High","Low") -> Low | V10: =Q10-P10 -> 103 | W10: =(Q10/P10)*100 -> 371.05263
A11: NFX-100010 | B11: Dark Legacy | C11: Movie | D11: Horror | E11: 2014 | F11: USA | G11: 2023-11-04 | H11: 108 | I11: 16+ | J11: 6 | K11: 229.3 | L11: French | M11: Bong Joon-ho | N11: Emma Stone | P11: 56 | Q11: 315.8 | R11: =_xlfn.IFS(J11>=8,"Hit",J11>=6,"Average",J11<6,"Flop") -> Average | S11: =_xlfn.IFS(K11>=400,"Blockbuster",K11>=200,"Popular",K11<200,"Normal") -> Popular | T11: =IF(OR(I11="PG",I11="G"),"Yes","No") -> No | U11: =IF(P11>=100,"High","Low") -> Low | V11: =Q11-P11 -> 259.8 | W11: =(Q11/P11)*100 -> 563.92857
A12: NFX-100011 | B12: Hidden Frontier 1 | C12: TV Show | D12: Adventure | E12: 2014 | F12: India | G12: 2019-01-27 | H12: 34 | I12: 16+ | J12: 5.6 | K12: 240.6 | L12: Korean | M12: Guillermo del Toro | N12: Song Kang-ho | O12: 1 | P12: 13 | Q12: 32.2 | R12: =_xlfn.IFS(J12>=8,"Hit",J12>=6,"Average",J12<6,"Flop") -> Flop | S12: =_xlfn.IFS(K12>=400,"Blockbuster",K12>=200,"Popular",K12<200,"Normal") -> Popular | T12: =IF(OR(I12="PG",I12="G"),"Yes","No") -> No | U12: =IF(P12>=100,"High","Low") -> Low | V12: =Q12-P12 -> 19.2 | W12: =(Q12/P12)*100 -> 247.69231
A13: NFX-100012 | B13: Lost Storm | C13: Movie | D13: Sci-Fi | E13: 2013 | F13: France | G13: 2019-03-03 | H13: 159 | I13: G | J13: 4.8 | K13: 404.3 | L13: French | M13: Denis Villeneuve | N13: Leonardo DiCaprio | P13: 40 | Q13: 129.1 | R13: =_xlfn.IFS(J13>=8,"Hit",J13>=6,"Average",J13<6,"Flop") -> Flop | S13: =_xlfn.IFS(K13>=400,"Blockbuster",K13>=200,"Popular",K13<200,"Normal") -> Blockbuster | T13: =IF(OR(I13="PG",I13="G"),"Yes","No") -> Yes | U13: =IF(P13>=100,"High","Low") -> Low | V13: =Q13-P13 -> 89.1 | W13: =(Q13/P13)*100 -> 322.75
A14: NFX-100013 | B14: Shadow Odyssey 1 | C14: Movie | D14: Sci-Fi | E14: 2001 | F14: Germany | G14: 2023-04-12 | H14: 117 | I14: PG | J14: 6 | K14: 3.2 | L14: Spanish | M14: Rajkumar Hirani | N14: Ryan Gosling | P14: 53 | Q14: 104.9 | R14: =_xlfn.IFS(J14>=8,"Hit",J14>=6,"Average",J14<6,"Flop") -> Average | S14: =_xlfn.IFS(K14>=400,"Blockbuster",K14>=200,"Popular",K14<200,"Normal") -> Normal | T14: =IF(OR(I14="PG",I14="G"),"Yes","No") -> Yes | U14: =IF(P14>=100,"High","Low") -> Low | V14: =Q14-P14 -> 51.9 | W14: =(Q14/P14)*100 -> 197.92453
A15: NFX-100014 | B15: Last Legacy | C15: TV Show | D15: Fantasy | E15: 2023 | F15: South Korea | G15: 2021-02-03 | H15: 44 | I15: PG | J15: 4.9 | K15: 599.3 | L15: Japanese | M15: Martin Scorsese | N15: Ranbir Kapoor | O15: 3 | P15: 6 | Q15: 33 | R15: =_xlfn.IFS(J15>=8,"Hit",J15>=6,"Average",J15<6,"Flop") -> Flop | S15: =_xlfn.IFS(K15>=400,"Blockbuster",K15>=200,"Popular",K15<200,"Normal") -> Blockbuster | T15: =IF(OR(I15="PG",I15="G"),"Yes","No") -> Yes | U15: =IF(P15>=100,"High","Low") -> Low | V15: =Q15-P15 -> 27 | W15: =(Q15/P15)*100 -> 550
A16: NFX-100015 | B16: Last Frontier | C16: Movie | D16: Fantasy | E16: 2001 | F16: Canada | G16: 2020-07-27 | H16: 111 | I16: 18+ | J16: 9.2 | K16: 506.4 | L16: English | M16: Zoya Akhtar | N16: Ryan Gosling | P16: 198 | Q16: 796.2 | R16: =_xlfn.IFS(J16>=8,"Hit",J16>=6,"Average",J16<6,"Flop") -> Hit | S16: =_xlfn.IFS(K16>=400,"Blockbuster",K16>=200,"Popular",K16<200,"Normal") -> Blockbuster | T16: =IF(OR(I16="PG",I16="G"),"Yes","No") -> No | U16: =IF(P16>=100,"High","Low") -> High | V16: =Q16-P16 -> 598.2 | W16: =(Q16/P16)*100 -> 402.12121
A17: NFX-100016 | B17: Last Frontier 2 | C17: TV Show | D17: Romance | E17: 2023 | F17: USA | G17: 2020-10-07 | H17: 38 | I17: 18+ | J17: 6.5 | K17: 289.3 | L17: Korean | M17: Steven Spielberg | N17: Tom Hardy | O17: 6 | P17: 55 | Q17: 323.1 | R17: =_xlfn.IFS(J17>=8,"Hit",J17>=6,"Average",J17<6,"Flop") -> Average | S17: =_xlfn.IFS(K17>=400,"Blockbuster",K17>=200,"Popular",K17<200,"Normal") -> Popular | T17: =IF(OR(I17="PG",I17="G"),"Yes","No") -> No | U17: =IF(P17>=100,"High","Low") -> Low | V17: =Q17-P17 -> 268.1 | W17: =(Q17/P17)*100 -> 587.45455
A18: NFX-100017 | B18: Hidden Journey 6 | C18: Movie | D18: Documentary | E18: 2016 | F18: USA | G18: 2023-10-22 | H18: 158 | I18: 18+ | J18: 6 | K18: 131.3 | L18: Korean | M18: Anurag Kashyap | N18: Deepika Padukone | P18: 83 | Q18: 176.8 | R18: =_xlfn.IFS(J18>=8,"Hit",J18>=6,"Average",J18<6,"Flop") -> Average | S18: =_xlfn.IFS(K18>=400,"Blockbuster",K18>=200,"Popular",K18<200,"Normal") -> Normal | T18: =IF(OR(I18="PG",I18="G"),"Yes","No") -> No | U18: =IF(P18>=100,"High","Low") -> Low | V18: =Q18-P18 -> 93.8 | W18: =(Q18/P18)*100 -> 213.01205
A19: NFX-100018 | B19: Burning Legacy | C19: Movie | D19: Thriller | E19: 2017 | F19: Japan | G19: 2022-06-05 | H19: 115 | I19: 18+ | J19: 5.6 | K19: 332.9 | L19: Hindi | M19: Sanjay Leela Bhansali | N19: Timothée Chalamet | P19: 171 | Q19: 809.6 | R19: =_xlfn.IFS(J19>=8,"Hit",J19>=6,"Average",J19<6,"Flop") -> Flop | S19: =_xlfn.IFS(K19>=400,"Blockbuster",K19>=200,"Popular",K19<200,"Normal") -> Popular | T19: =IF(OR(I19="PG",I19="G"),"Yes","No") -> No | U19: =IF(P19>=100,"High","Low") -> High | V19: =Q19-P19 -> 638.6 | W19: =(Q19/P19)*100 -> 473.45029
A20: NFX-100019 | B20: Fading Horizon 1 | C20: Movie | D20: Sci-Fi | E20: 2011 | F20: France | G20: 2024-06-25 | H20: 113 | I20: PG-13 | J20: 7.5 | K20: 242.6 | L20: French | M20: Bong Joon-ho | N20: Robert Downey Jr. | P20: 58 | Q20: 155 | R20: =_xlfn.IFS(J20>=8,"Hit",J20>=6,"Average",J20<6,"Flop") -> Average | S20: =_xlfn.IFS(K20>=400,"Blockbuster",K20>=200,"Popular",K20<200,"Normal") -> Popular | T20: =IF(OR(I20="PG",I20="G"),"Yes","No") -> No | U20: =IF(P20>=100,"High","Low") -> Low | V20: =Q20-P20 -> 97 | W20: =(Q20/P20)*100 -> 267.24138
A21: NFX-100020 | B21: Fading Echo 3 | C21: Movie | D21: Adventure | E21: 2015 | F21: India | G21: 2018-04-16 | H21: 154 | I21: PG | J21: 6.9 | K21: 83.4 | L21: Spanish | M21: James Cameron | N21: Ranbir Kapoor | P21: 175 | Q21: 428.2 | R21: =_xlfn.IFS(J21>=8,"Hit",J21>=6,"Average",J21<6,"Flop") -> Average | S21: =_xlfn.IFS(K21>=400,"Blockbuster",K21>=200,"Popular",K21<200,"Normal") -> Normal | T21: =IF(OR(I21="PG",I21="G"),"Yes","No") -> Yes | U21: =IF(P21>=100,"High","Low") -> High | V21: =Q21-P21 -> 253.2 | W21: =(Q21/P21)*100 -> 244.68571
A22: NFX-100021 | B22: Fading Valley | C22: TV Show | D22: Romance | E22: 2009 | F22: USA | G22: 2018-05-26 | H22: 35 | I22: PG | J22: 9.3 | K22: 587.8 | L22: Hindi | M22: Bong Joon-ho | N22: Chris Evans | O22: 5 | P22: 47 | Q22: 76.8 | R22: =_xlfn.IFS(J22>=8,"Hit",J22>=6,"Average",J22<6,"Flop") -> Hit | S22: =_xlfn.IFS(K22>=400,"Blockbuster",K22>=200,"Popular",K22<200,"Normal") -> Blockbuster | T22: =IF(OR(I22="PG",I22="G"),"Yes","No") -> Yes | U22: =IF(P22>=100,"High","Low") -> Low | V22: =Q22-P22 -> 29.8 | W22: =(Q22/P22)*100 -> 163.40426
A23: NFX-100022 | B23: Secret Storm 7 | C23: Movie | D23: Thriller | E23: 2010 | F23: UK | G23: 2018-06-21 | H23: 125 | I23: G | J23: 5.6 | K23: 271 | L23: Spanish | M23: James Cameron | N23: Emma Stone | P23: 104 | Q23: 318.6 | R23: =_xlfn.IFS(J23>=8,"Hit",J23>=6,"Average",J23<6,"Flop") -> Flop | S23: =_xlfn.IFS(K23>=400,"Blockbuster",K23>=200,"Popular",K23<200,"Normal") -> Popular | T23: =IF(OR(I23="PG",I23="G"),"Yes","No") -> Yes | U23: =IF(P23>=100,"High","Low") -> High | V23: =Q23-P23 -> 214.6 | W23: =(Q23/P23)*100 -> 306.34615
A24: NFX-100023 | B24: Secret Journey | C24: Movie | D24: Comedy | E24: 2009 | F24: UK | G24: 2022-05-17 | H24: 119 | I24: 16+ | J24: 4.8 | K24: 511.1 | L24: Japanese | M24: Park Chan-wook | N24: Emma Stone | P24: 64 | Q24: 97.1 | R24: =_xlfn.IFS(J24>=8,"Hit",J24>=6,"Average",J24<6,"Flop") -> Flop | S24: =_xlfn.IFS(K24>=400,"Blockbuster",K24>=200,"Popular",K24<200,"Normal") -> Blockbuster | T24: =IF(OR(I24="PG",I24="G"),"Yes","No") -> No | U24: =IF(P24>=100,"High","Low") -> Low | V24: =Q24-P24 -> 33.1 | W24: =(Q24/P24)*100 -> 151.71875
A25: NFX-100024 | B25: Midnight Legacy 3 | C25: Movie | D25: Romance | E25: 2007 | F25: France | G25: 2019-04-29 | H25: 135 | I25: PG | J25: 6.1 | K25: 555.7 | L25: French | M25: Greta Gerwig | N25: Song Kang-ho | P25: 122 | Q25: 615.7 | R25: =_xlfn.IFS(J25>=8,"Hit",J25>=6,"Average",J25<6,"Flop") -> Average | S25: =_xlfn.IFS(K25>=400,"Blockbuster",K25>=200,"Popular",K25<200,"Normal") -> Blockbuster | T25: =IF(OR(I25="PG",I25="G"),"Yes","No") -> Yes | U25: =IF(P25>=100,"High","Low") -> High | V25: =Q25-P25 -> 493.7 | W25: =(Q25/P25)*100 -> 504.67213
A26: NFX-100025 | B26: Last Protocol 3 | C26: Movie | D26: Crime | E26: 2013 | F26: France | G26: 2022-01-18 | H26: 101 | I26: 16+ | J26: 7.5 | K26: 475.5 | L26: Japanese | M26: James Cameron | N26: Jennifer Lawrence | P26: 39 | Q26: 175.3 | R26: =_xlfn.IFS(J26>=8,"Hit",J26>=6,"Average",J26<6,"Flop") -> Average | S26: =_xlfn.IFS(K26>=400,"Blockbuster",K26>=200,"Popular",K26<200,"Normal") -> Blockbuster | T26: =IF(OR(I26="PG",I26="G"),"Yes","No") -> No | U26: =IF(P26>=100,"High","Low") -> Low | V26: =Q26-P26 -> 136.3 | W26: =(Q26/P26)*100 -> 449.48718
A27: NFX-100026 | B27: Last Frontier 8 | C27: TV Show | D27: Crime | E27: 2010 | F27: South Korea | G27: 2022-09-04 | H27: 53 | I27: PG | J27: 9.1 | K27: 165 | L27: French | M27: Steven Spielberg | N27: Scarlett Johansson | O27: 8 | P27: 169 | Q27: 1000.7 | R27: =_xlfn.IFS(J27>=8,"Hit",J27>=6,"Average",J27<6,"Flop") -> Hit | S27: =_xlfn.IFS(K27>=400,"Blockbuster",K27>=200,"Popular",K27<200,"Normal") -> Normal | T27: =IF(OR(I27="PG",I27="G"),"Yes","No") -> Yes | U27: =IF(P27>=100,"High","Low") -> High | V27: =Q27-P27 -> 831.7 | W27: =(Q27/P27)*100 -> 592.13018
A28: NFX-100027 | B28: Rising Protocol | C28: Movie | D28: Documentary | E28: 2024 | F28: Japan | G28: 2018-08-27 | H28: 115 | I28: 16+ | J28: 8.4 | K28: 196.7 | L28: English | M28: Ridley Scott | N28: Shah Rukh Khan | P28: 137 | Q28: 496.6 | R28: =_xlfn.IFS(J28>=8,"Hit",J28>=6,"Average",J28<6,"Flop") -> Hit | S28: =_xlfn.IFS(K28>=400,"Blockbuster",K28>=200,"Popular",K28<200,"Normal") -> Normal | T28: =IF(OR(I28="PG",I28="G"),"Yes","No") -> No | U28: =IF(P28>=100,"High","Low") -> High | V28: =Q28-P28 -> 359.6 | W28: =(Q28/P28)*100 -> 362.48175
A29: NFX-100028 | B29: Hidden Code | C29: Movie | D29: Horror | E29: 2019 | F29: Canada | G29: 2024-06-12 | H29: 158 | I29: PG-13 | J29: 9.3 | K29: 86.5 | L29: French | M29: Rajkumar Hirani | N29: Brad Pitt | P29: 89 | Q29: 255 | R29: =_xlfn.IFS(J29>=8,"Hit",J29>=6,"Average",J29<6,"Flop") -> Hit | S29: =_xlfn.IFS(K29>=400,"Blockbuster",K29>=200,"Popular",K29<200,"Normal") -> Normal | T29: =IF(OR(I29="PG",I29="G"),"Yes","No") -> No | U29: =IF(P29>=100,"High","Low") -> Low | V29: =Q29-P29 -> 166 | W29: =(Q29/P29)*100 -> 286.51685
A30: NFX-100029 | B30: Burning Chronicles 6 | C30: Movie | D30: Action | E30: 2022 | F30: Japan | G30: 2018-12-21 | H30: 164 | I30: G | J30: 9.6 | K30: 368.6 | L30: Japanese | M30: Zoya Akhtar | N30: Brad Pitt | P30: 48 | Q30: 88.3 | R30: =_xlfn.IFS(J30>=8,"Hit",J30>=6,"Average",J30<6,"Flop") -> Hit | S30: =_xlfn.IFS(K30>=400,"Blockbuster",K30>=200,"Popular",K30<200,"Normal") -> Popular | T30: =IF(OR(I30="PG",I30="G"),"Yes","No") -> Yes | U30: =IF(P30>=100,"High","Low") -> Low | V30: =Q30-P30 -> 40.3 | W30: =(Q30/P30)*100 -> 183.95833
A31: NFX-100030 | B31: Broken Chronicles | C31: Movie | D31: Documentary | E31: 2021 | F31: UK | G31: 2018-07-15 | H31: 84 | I31: PG | J31: 9 | K31: 234.7 | L31: Korean | M31: James Cameron | N31: Chris Evans | P31: 83 | Q31: 369.5 | R31: =_xlfn.IFS(J31>=8,"Hit",J31>=6,"Average",J31<6,"Flop") -> Hit | S31: =_xlfn.IFS(K31>=400,"Blockbuster",K31>=200,"Popular",K31<200,"Normal") -> Popular | T31: =IF(OR(I31="PG",I31="G"),"Yes","No") -> Yes | U31: =IF(P31>=100,"High","Low") -> Low | V31: =Q31-P31 -> 286.5 | W31: =(Q31/P31)*100 -> 445.18072
A32: NFX-100031 | B32: Shadow Journey 6 | C32: TV Show | D32: Action | E32: 2006 | F32: Japan | G32: 2023-10-18 | H32: 41 | I32: G | J32: 8.4 | K32: 210.1 | L32: German | M32: James Cameron | N32: Deepika Padukone | O32: 2 | P32: 194 | Q32: 658.4 | R32: =_xlfn.IFS(J32>=8,"Hit",J32>=6,"Average",J32<6,"Flop") -> Hit | S32: =_xlfn.IFS(K32>=400,"Blockbuster",K32>=200,"Popular",K32<200,"Normal") -> Popular | T32: =IF(OR(I32="PG",I32="G"),"Yes","No") -> Yes | U32: =IF(P32>=100,"High","Low") -> High | V32: =Q32-P32 -> 464.4 | W32: =(Q32/P32)*100 -> 339.38144
A33: NFX-100032 | B33: Shadow Valley 1 | C33: Movie | D33: Action | E33: 2017 | F33: UK | G33: 2024-05-29 | H33: 152 | I33: PG-13 | J33: 8.6 | K33: 584.8 | L33: English | M33: Denis Villeneuve | N33: Jennifer Lawrence | P33: 134 | Q33: 583.2 | R33: =_xlfn.IFS(J33>=8,"Hit",J33>=6,"Average",J33<6,"Flop") -> Hit | S33: =_xlfn.IFS(K33>=400,"Blockbuster",K33>=200,"Popular",K33<200,"Normal") -> Blockbuster | T33: =IF(OR(I33="PG",I33="G"),"Yes","No") -> No | U33: =IF(P33>=100,"High","Low") -> High | V33: =Q33-P33 -> 449.2 | W33: =(Q33/P33)*100 -> 435.22388
A34: NFX-100033 | B34: Dark Frontier | C34: Movie | D34: Comedy | E34: 2011 | F34: Canada | G34: 2020-08-18 | H34: 145 | I34: PG | J34: 6.5 | K34: 539.8 | L34: English | M34: Sanjay Leela Bhansali | N34: Lee Jung-jae | P34: 48 | Q34: 106.8 | R34: =_xlfn.IFS(J34>=8,"Hit",J34>=6,"Average",J34<6,"Flop") -> Average | S34: =_xlfn.IFS(K34>=400,"Blockbuster",K34>=200,"Popular",K34<200,"Normal") -> Blockbuster | T34: =IF(OR(I34="PG",I34="G"),"Yes","No") -> Yes | U34: =IF(P34>=100,"High","Low") -> Low | V34: =Q34-P34 -> 58.8 | W34: =(Q34/P34)*100 -> 222.5
A35: NFX-100034 | B35: Secret Archive | C35: TV Show | D35: Fantasy | E35: 2017 | F35: Australia | G35: 2023-04-08 | H35: 51 | I35: G | J35: 6.7 | K35: 354.9 | L35: Korean | M35: Martin Scorsese | N35: Leonardo DiCaprio | O35: 7 | P35: 51 | Q35: 306.1 | R35: =_xlfn.IFS(J35>=8,"Hit",J35>=6,"Average",J35<6,"Flop") -> Average | S35: =_xlfn.IFS(K35>=400,"Blockbuster",K35>=200,"Popular",K35<200,"Normal") -> Popular | T35: =IF(OR(I35="PG",I35="G"),"Yes","No") -> Yes | U35: =IF(P35>=100,"High","Low") -> Low | V35: =Q35-P35 -> 255.1 | W35: =(Q35/P35)*100 -> 600.19608
A36: NFX-100035 | B36: Crystal Journey | C36: TV Show | D36: Fantasy | E36: 2001 | F36: South Korea | G36: 2022-02-17 | H36: 60 | I36: 18+ | J36: 5.4 | K36: 334.2 | L36: Hindi | M36: Denis Villeneuve | N36: Jennifer Lawrence | O36: 7 | P36: 22 | Q36: 126.2 | R36: =_xlfn.IFS(J36>=8,"Hit",J36>=6,"Average",J36<6,"Flop") -> Flop | S36: =_xlfn.IFS(K36>=400,"Blockbuster",K36>=200,"Popular",K36<200,"Normal") -> Popular | T36: =IF(OR(I36="PG",I36="G"),"Yes","No") -> No | U36: =IF(P36>=100,"High","Low") -> Low | V36: =Q36-P36 -> 104.2 | W36: =(Q36/P36)*100 -> 573.63636
A37: NFX-100036 | B37: Fading Signal | C37: TV Show | D37: Romance | E37: 2009 | F37: Japan | G37: 2022-10-09 | H37: 36 | I37: 18+ | J37: 7.2 | K37: 496.9 | L37: Korean | M37: Rajkumar Hirani | N37: Timothée Chalamet | O37: 4 | P37: 37 | Q37: 143 | R37: =_xlfn.IFS(J37>=8,"Hit",J37>=6,"Average",J37<6,"Flop") -> Average | S37: =_xlfn.IFS(K37>=400,"Blockbuster",K37>=200,"Popular",K37<200,"Normal") -> Blockbuster | T37: =IF(OR(I37="PG",I37="G"),"Yes","No") -> No | U37: =IF(P37>=100,"High","Low") -> Low | V37: =Q37-P37 -> 106 | W37: =(Q37/P37)*100 -> 386.48649
A38: NFX-100037 | B38: Lost Journey | C38: Movie | D38: Adventure | E38: 2025 | F38: Australia | G38: 2023-08-06 | H38: 134 | I38: 16+ | J38: 6 | K38: 130 | L38: Korean | M38: Denis Villeneuve | N38: Emma Stone | P38: 169 | Q38: 844.6 | R38: =_xlfn.IFS(J38>=8,"Hit",J38>=6,"Average",J38<6,"Flop") -> Average | S38: =_xlfn.IFS(K38>=400,"Blockbuster",K38>=200,"Popular",K38<200,"Normal") -> Normal | T38: =IF(OR(I38="PG",I38="G"),"Yes","No") -> No | U38: =IF(P38>=100,"High","Low") -> High | V38: =Q38-P38 -> 675.6 | W38: =(Q38/P38)*100 -> 499.76331
A39: NFX-100038 | B39: Fading Chronicles | C39: Movie | D39: Drama | E39: 2006 | F39: Japan | G39: 2024-06-20 | H39: 113 | I39: 18+ | J39: 5.4 | K39: 53.1 | L39: Korean | M39: Ridley Scott | N39: Timothée Chalamet | P39: 29 | Q39: 103.3 | R39: =_xlfn.IFS(J39>=8,"Hit",J39>=6,"Average",J39<6,"Flop") -> Flop | S39: =_xlfn.IFS(K39>=400,"Blockbuster",K39>=200,"Popular",K39<200,"Normal") -> Normal | T39: =IF(OR(I39="PG",I39="G"),"Yes","No") -> No | U39: =IF(P39>=100,"High","Low") -> Low | V39: =Q39-P39 -> 74.3 | W39: =(Q39/P39)*100 -> 356.2069
A40: NFX-100039 | B40: Dark Signal | C40: TV Show | D40: Thriller | E40: 2015 | F40: India | G40: 2023-06-04 | H40: 41 | I40: PG | J40: 8.2 | K40: 309.9 | L40: French | M40: Sanjay Leela Bhansali | N40: Song Kang-ho | O40: 4 | P40: 20 | Q40: 55.1 | R40: =_xlfn.IFS(J40>=8,"Hit",J40>=6,"Average",J40<6,"Flop") -> Hit | S40: =_xlfn.IFS(K40>=400,"Blockbuster",K40>=200,"Popular",K40<200,"Normal") -> Popular | T40: =IF(OR(I40="PG",I40="G"),"Yes","No") -> Yes | U40: =IF(P40>=100,"High","Low") -> Low | V40: =Q40-P40 -> 35.1 | W40: =(Q40/P40)*100 -> 275.5
...

Sheet Q_a
A1: 1 | F1: Count | K1: 8 | O1: Average
A2: Count the total number of content titles in the dataset | F2: =COUNTA(Netflix_Data!B2:B1501) -> 1500 | K2: Find the average budget of all content | O2: =AVERAGE(Netflix_Data!P2:P1501) -> 101.93667
A5: 2 | E5: Type | F5: Count | K5: 9 | P5: MAX
A6: Count how many Movies/TV Shows are there | E6: TV Show | F6: =COUNTIF(Netflix_Data!C2:C1501,E6) -> 743 | K6: Find the maximum revenue generated by any title | P6: =MAX(Netflix_Data!Q2:Q1501) -> 1265.2
A9: 3 | E9: Average | K9: 10 | O9: MIN
A10: Find the average IMDb rating of all content | E10: =AVERAGE(Netflix_Data!J2:J1501) -> 7.0219333 | K10: Find the minimum duration of content | O10: =MIN(Netflix_Data!H2:H1501) -> 30
A13: 4 | K13: 11 | O13: Total Count
A14: Find the maximum IMDb rating | D14: =MAX(Netflix_Data!J2:J1501) -> 9.6 | K14: Count how many Action genre titles exist | O14: =COUNTIF(Netflix_Data!D2:D1501,"Action") -> 134
A15: Find the minimun IMDb rating | D15: =MIN(Netflix_Data!J2:J1501) -> 4.5
K17: 12 | O17: Country | P17: Total Count
A18: 5 | E18: Total Views | K18: Count how many titles were produced in | O18: UK | P18: =COUNTIF(Netflix_Data!F2:F1501,Q_a!O18) -> 150
A19: Calculate total views (in millions) of all content | E19: =SUM(Netflix_Data!K2:K1501) -> 449993
K21: 13 | P21: IMDb Rating | Q21: Count
A22: 6 | E22: Country | F22: Total Views | K22: Count how many contents have IMDb rating above | P22: 9 | Q22: =COUNTIF(Netflix_Data!J2:J1501,Q_a!P22) -> 23
A23: Find total views of content produced in | E23: USA | F23: =SUMIF(Netflix_Data!A1:Q1501,Q_a!E23,Netflix_Data!K2:K1501) -> 17365
K25: 14 | N25: Genre | O25: Rating
A26: 7 | F26: Average | K26: Find average IMDb rating | N26: Action | O26: =ROUNDUP(AVERAGEIFS(Netflix_Data!J1:J1501,Netflix_Data!D1:D1501,Q_a!N26),1) -> 7.1
A27: Find average rating of content released after 2020 | F27: =ROUNDUP(AVERAGEIFS(Netflix_Data!J2:J1501,Netflix_Data!E2:E1501,">2020"),1) -> 7.2
G30: 15 | J30: Seasons | K30: Count
G31: Count how many TV Shows have | J31: <6 | K31: =COUNTIFS(Netflix_Data!C1:C1501,"TV Show",Netflix_Data!O1:O1501,Q_a!J31) -> 450

Sheet Q_b
A1: Q) Create a search box where entering Content_ID returns Title, Genre and IMDb rating
A3: Content_ID | B3: Title | C3: Genre | D3: IMDb rating
A4: NFX-100009 | B4: =VLOOKUP(A4,Netflix_Data!A1:U1501,2,0) -> Midnight Empire 5 | C4: =VLOOKUP(A4,Netflix_Data!A1:U1501,4,0) -> Fantasy | D4: =VLOOKUP(A4,Netflix_Data!A1:U1501,10,0) -> 4.9
A7: Q) Return the details by giving Title
A9: Title | B9: Director | C9: Revenue_Million_USD | D9: Genre | E9: Views_Millions | F9: Lead_Actor | G9: Language
A10: Midnight Empire 5 | B10: =VLOOKUP($A10,Netflix_Data!$B$1:$U$1501,MATCH(B9,Netflix_Data!$B$1:$U$1,0),0) -> Guillermo del Toro | C10: =VLOOKUP($A10,Netflix_Data!$B$1:$U$1501,MATCH(C9,Netflix_Data!$B$1:$U$1,0),0) -> 141 | D10: =VLOOKUP($A10,Netflix_Data!$B$1:$U$1501,MATCH(D9,Netflix_Data!$B$1:$U$1,0),0) -> Fantasy | E10: =VLOOKUP($A10,Netflix_Data!$B$1:$U$1501,MATCH(E9,Netflix_Data!$B$1:$U$1,0),0) -> 590.4 | F10: =VLOOKUP($A10,Netflix_Data!$B$1:$U$1501,MATCH(F9,Netflix_Data!$B$1:$U$1,0),0) -> Chris Evans | G10: =VLOOKUP($A10,Netflix_Data!$B$1:$U$1501,MATCH(G9,Netflix_Data!$B$1:$U$1,0),0) -> Spanish
A13: Q) Find top 5 most viewed titles
A15: Views | B15: Title
A16: =LARGE(Netflix_Data!K:K,ROW(A1)) -> 599.3 | B16: =INDEX(Netflix_Data!B:B,MATCH(A16,Netflix_Data!K:K,0)) -> Last Legacy
A17: =LARGE(Netflix_Data!K:K,ROW(A2)) -> 598.7 | B17: =INDEX(Netflix_Data!B:B,MATCH(A17,Netflix_Data!K:K,0)) -> Silent Odyssey 8
A18: =LARGE(Netflix_Data!K:K,ROW(A3)) -> 598.6 | B18: =INDEX(Netflix_Data!B:B,MATCH(A18,Netflix_Data!K:K,0)) -> Shadow Frontier 2
A19: =LARGE(Netflix_Data!K:K,ROW(A4)) -> 598.4 | B19: =INDEX(Netflix_Data!B:B,MATCH(A19,Netflix_Data!K:K,0)) -> Burning Protocol 7
A20: =LARGE(Netflix_Data!K:K,ROW(A5)) -> 597.4 | B20: =INDEX(Netflix_Data!B:B,MATCH(A20,Netflix_Data!K:K,0)) -> Midnight City 5
A23: Q) Find top 5 highest revenue titles
A25: Highest Revenue | B25: Title
A26: =LARGE(Netflix_Data!Q:Q,ROW(A1)) -> 1265.2 | B26: =INDEX(Netflix_Data!B:B,MATCH(A26,Netflix_Data!Q:Q,0)) -> Lost Horizon 2
A27: =LARGE(Netflix_Data!Q:Q,ROW(A2)) -> 1243.4 | B27: =INDEX(Netflix_Data!B:B,MATCH(A27,Netflix_Data!Q:Q,0)) -> Fading Code 1
A28: =LARGE(Netflix_Data!Q:Q,ROW(A3)) -> 1238.5 | B28: =INDEX(Netflix_Data!B:B,MATCH(A28,Netflix_Data!Q:Q,0)) -> Hidden Frontier 8
A29: =LARGE(Netflix_Data!Q:Q,ROW(A4)) -> 1217.2 | B29: =INDEX(Netflix_Data!B:B,MATCH(A29,Netflix_Data!Q:Q,0)) -> Golden Odyssey 8
A30: =LARGE(Netflix_Data!Q:Q,ROW(A5)) -> 1209.8 | B30: =INDEX(Netflix_Data!B:B,MATCH(A30,Netflix_Data!Q:Q,0)) -> Burning Signal

Sheet Table
A1: Find number of titles by Genre | F1: Find average IMDb rating by Country | K1: Find total revenue by Genre
A3: Row Labels | B3: Count of Title | F3: Row Labels | G3: Average of IMDb_Rating | K3: Row Labels | L3: Sum of Revenue_Million_USD
A4: Action | B4: 134 | F4: Australia | G4: 6.8977941 | K4: Action | L4: 53729.3
A5: Adventure | B5: 149 | F5: Canada | G5: 7.0668966 | K5: Adventure | L5: 61214.7
A6: Comedy | B6: 119 | F6: France | G6: 7.0066176 | K6: Comedy | L6: 44643.2
A7: Crime | B7: 155 | F7: Germany | G7: 7.0875862 | K7: Crime | L7: 60829.9
A8: Documentary | B8: 133 | F8: India | G8: 7.1524691 | K8: Documentary | L8: 52959.7
A9: Drama | B9: 131 | F9: Japan | G9: 7.0892216 | K9: Drama | L9: 49652.7
A10: Fantasy | B10: 134 | F10: South Korea | G10: 7.0917197 | K10: Fantasy | L10: 56786
A11: Horror | B11: 139 | F11: Spain | G11: 6.7679104 | K11: Horror | L11: 53201.9
A12: Romance | B12: 147 | F12: UK | G12: 7.0046667 | K12: Romance | L12: 58614.6
A13: Sci-Fi | B13: 127 | F13: USA | G13: 6.9994048 | K13: Sci-Fi | L13: 49477
A14: Thriller | B14: 132 | F14: Grand Total | G14: 7.0219333 | K14: Thriller | L14: 48980.9
A15: Grand Total | B15: 1500 | K15: Grand Total | L15: 590089.9

Sheet Chart
F1: Chart showing Views by Genre
B4: Row Labels | C4: Sum of Views_Millions
B5: Action | C5: 38416.7
B6: Adventure | C6: 45281.2
B7: Comedy | C7: 35044
B8: Crime | C8: 43798.3
B9: Documentary | C9: 40070.3
B10: Drama | C10: 40065
B11: Fantasy | C11: 40997.1
B12: Horror | C12: 42325.2
B13: Romance | C13: 45408
B14: Sci-Fi | C14: 38258.6
B15: Thriller | C15: 40328.6
B16: Grand Total | C16: 449993
